# Обработка исключений

В JavaScript обработка ошибок осуществляется с использованием механизма исключений (exceptions). Исключения возникают в ситуациях, когда исполнение кода сталкивается с ошибкой или неожиданным условием, при этом выполнение программы останавливается и ошибка выводится в консоли. Для обработки ошибок используются конструкции try, catch, throw, finally.

1. `try...catch`. Конструкция состоит из двух основных блоков: `try` и `catch`.

```javascript

try {

//код

} catch (err) { // <- Объект ошибки.
    // Обработка исключений.
} finally {
    // Код выполнится в любом случае.
}

```

Конструкция выше, обрабатывается так:

1. Сначала выполняется код внутри блока try {...}.

2. Если в нём нет ошибок, то блок catch(err) игнорируется: выполнение доходит до конца try и потом далее, полностью пропуская catch.

3. Если же в нём возникает ошибка, то выполнение try прерывается, и поток управления переходит в начало catch(err).Переменная err (можно использовать любое имя) содержит объект ошибки с подробной информацией о произошедшем.

Блок кода, находящийся в блоке `finally`, выполнится в любом случае, независимо от возникновения ошибки.

2. Генерация собственных ошибок.

Оператор `throw` позволяет генерировать собственные исключения.

```javascript
function divide(a, b) {
  if (b === 0) {
    throw new Error('Деление на ноль недопустимо');
  }
  return a / b;
}

try {
  console.log(divide(10, 2));  
  console.log(divide(10, 0));  // Ошибка: деление на ноль.
} catch (error) {
  console.error(error.message);
}
```

В примере выше можно увидеть, что если второй параметр функции равен 0, то мы создаём исключение с помощью оператора `throw` и объект ошибки с переданным сообщением (message), где сможем обработать это в блоке `catch`.
